Workbook

Sheet Legend
A1: DonorLink usability study - Results and analysis (Workbook B)
A3: Proxy-study demonstration data only. SYNTHETIC PROXY EVALUATION ONLY — not a human participant session; validate with real Android users.
A5: 1. Paste VALUES (Paste Special > Values) of the whole Sessions, Observations and SUS sheets from observation-sheet.xlsx, and the Issues sheet from issue-log.xlsx.
A6: 2. Read Summary (recruitment check, SUS), Task Metrics (per task) and Table 16 (same columns as the report's Table 16).
A7: Denominators are explicit: 'Attempted' = rows whose outcome is not blank and not 'Not attempted'. Application-blocked attempts stay in 'Attempted' but never count as completed.
A8: Completion rate follows the report: unaided completions / participants who attempted (PDF §9.3). Assisted completion and abandonment are reported separately.
A9: Mean time = mean seconds of COMPLETED attempts only, shown for unaided and for all completions. Abandoned and blocked attempts are excluded from time.
A10: SUS = Brooke scoring on the SUS sheet. With fewer than 10 participants treat the mean as indicative; the reference point ~68 is a commonly cited average.
A12: Colour key
A13: Pale yellow, blue text = you type here
A14: Grey-blue, black text = formula, do not type here

Sheet Summary
A1: Summary
A3: RECRUITMENT (PDF §9.2)
A4: Participants who consented and took part (N) | B4: =COUNTIFS(Sessions!$N$2:$N$16,"Yes") -> 5 | C4: Count of rows with 'Yes' consent.
A5: ... who have donated blood | B5: =COUNTIFS(Sessions!$N$2:$N$16,"Yes",Sessions!$J$2:$J$16,"Y") -> 3 | C5: Target: at least 2.
A6: ... who have searched for blood for someone | B6: =COUNTIFS(Sessions!$N$2:$N$16,"Yes",Sessions!$K$2:$K$16,"Y") -> 3 | C6: Target: at least 2.
A7: ... who are group members (must be 0) | B7: =COUNTIFS(Sessions!$N$2:$N$16,"Yes",Sessions!$M$2:$M$16,"Y") -> 0 | C7: Group members are excluded.
A8: ... who used the M02 prototype (learning effect) | B8: =COUNTIFS(Sessions!$N$2:$N$16,"Yes",Sessions!$L$2:$L$16,"Y") -> 0 | C8: Excluded 'where possible'; report if >0.
A9: Recruitment criteria met? | B9: =IF(AND(B4>=5,B4<=8,B5>=2,B6>=2,B7=0),"Met","NOT met (5-8 participants, >=2 donors, >=2 searchers, 0 group members)") -> Met | C9: Evaluates live as data is pasted.
A11: SYSTEM USABILITY SCALE
A12: SUS questionnaires fully answered (n) | B12: =COUNT(SUS!$L$2:$L$16) -> 5 | C12: Only complete questionnaires are scored.
A14: SUS mean (0-100) | B14: =IF(B12=0,"",AVERAGE(SUS!$L$2:$L$16)) -> 70 | C14: Mean of per-participant SUS scores.
A15: SUS standard deviation | B15: =IF(B12<2,"",STDEV(SUS!$L$2:$L$16)) -> 9.8425098 | C15: Needs at least 2 scores.
A16: SUS minimum | B16: =IF(B12=0,"",MIN(SUS!$L$2:$L$16)) -> 52.5
A17: SUS maximum | B17: =IF(B12=0,"",MAX(SUS!$L$2:$L$16)) -> 75
A18: Reading (indicative only) | B18: =IF(B14="","",IF(B14>=80.3,"Well above the ~68 average",IF(B14>=68,"At or above the ~68 average",IF(B14>=51,"Below the ~68 average","Poor (below ~51)"))))&IF(B12<10," - small sample (n<10), interpret with caution","") -> At or above the ~68 average - small sample (n<10), interpret with caution | C18: Cut-offs after Sauro & Lewis (report ref. [5]); not a pass/fail.
A20: TASKS (details on 'Task Metrics')
A21: Tasks with at least one attempt | B21: =COUNTIF('Task Metrics'!$C$2:$C$7,">0") -> 6 | C21: Out of 6 required tasks.
A22: Application-blocked attempts (all tasks) | B22: =SUM('Task Metrics'!$G$2:$G$7) -> 0 | C22: Defects that stopped a task; not counted as completion.
A24: ISSUES (details on 'Issues')
A25: Observed issues logged (IDs starting WA-) | B25: =COUNTIF(Issues!$A$2:$A$100,"WA-*") -> 4
A26: ... severity 3-4 (High) | B26: =COUNTIFS(Issues!$A$2:$A$100,"WA-*",Issues!$H$2:$H$100,">=3") -> 3
A27: ... severity 2 (Medium) | B27: =COUNTIFS(Issues!$A$2:$A$100,"WA-*",Issues!$H$2:$H$100,2) -> 1
A28: ... severity 0-1 (Low / none) | B28: =COUNTIFS(Issues!$A$2:$A$100,"WA-*",Issues!$H$2:$H$100,"<=1",Issues!$H$2:$H$100,"<>") -> 0
A29: Candidate issues still unverified (CAND-) | B29: =COUNTIFS(Issues!$A$2:$A$100,"CAND-*",Issues!$M$2:$M$100,"Needs verification") -> 0 | C29: From code reading; not findings.

Sheet Task Metrics
A1: Task | B1: Title | C1: Attempted (N) | D1: Completed unaided | E1: Completed with assistance | F1: Abandoned | G1: Application-blocked | H1: Unaided completion rate (PDF def.) | I1: Assisted completion rate | J1: Total completion rate (unaided + assisted) | K1: Abandoned rate | L1: Unaided rate excl. blocked attempts | M1: Mean time, unaided (s) | N1: Mean time, all completed (s) | O1: Total errors | P1: Mean errors per attempt | Q1: Total assists | R1: Mean SEQ (1-7) | S1: Valid SEQ responses (n)
A2: T1 | B2: Sign in | C2: =COUNTIFS(Observations!$C$2:$C$200,$A2,Observations!$E$2:$E$200,"<>",Observations!$E$2:$E$200,"<>Not attempted") -> 5 | D2: =COUNTIFS(Observations!$C$2:$C$200,$A2,Observations!$E$2:$E$200,"Completed unaided") -> 5 | E2: =COUNTIFS(Observations!$C$2:$C$200,$A2,Observations!$E$2:$E$200,"Completed with assistance") -> 0 | F2: =COUNTIFS(Observations!$C$2:$C$200,$A2,Observations!$E$2:$E$200,"Abandoned") -> 0 | G2: =COUNTIFS(Observations!$C$2:$C$200,$A2,Observations!$E$2:$E$200,"Application-blocked") -> 0 | H2: =IF(C2=0,"",D2/C2) -> 1 | I2: =IF(C2=0,"",E2/C2) -> 0 | J2: =IF(C2=0,"",(D2+E2)/C2) -> 1 | K2: =IF(C2=0,"",F2/C2) -> 0 | L2: =IF(C2-G2<=0,"",D2/(C2-G2)) -> 1 | M2: =IF(COUNTIFS(Observations!$C$2:$C$200,$A2,Observations!$E$2:$E$200,"Completed unaided",Observations!$J$2:$J$200,">=0")=0,"",SUMIFS(Observations!$J$2:$J$200,Observations!$C$2:$C$200,$A2,Observations!$E$2:$E$200,"Completed unaided")/COUNTIFS(Observations!$C$2:$C$200,$A2,Observations!$E$2:$E$200,"Completed unaided",Observations!$J$2:$J$200,">=0")) -> 21.2 | N2: =IF(COUNTIFS(Observations!$C$2:$C$200,$A2,Observations!$E$2:$E$200,"Completed*",Observations!$J$2:$J$200,">=0")=0,"",SUMIFS(Observations!$J$2:$J$200,Observations!$C$2:$C$200,$A2,Observations!$E$2:$E$200,"Completed*")/COUNTIFS(Observations!$C$2:$C$200,$A2,Observations!$E$2:$E$200,"Completed*",Observations!$J$2:$J$200,">=0")) -> 21.2 | O2: =SUMIFS(Observations!$K$2:$K$200,Observations!$C$2:$C$200,$A2) -> 0 | P2: =IF(C2=0,"",O2/C2) -> 0 | Q2: =SUMIFS(Observations!$M$2:$M$200,Observations!$C$2:$C$200,$A2) -> 0 | R2: =IF(S2=0,"",SUMIFS(Observations!$P$2:$P$200,Observations!$C$2:$C$200,$A2,Observations!$P$2:$P$200,">=1")/S2) -> 7 | S2: =COUNTIFS(Observations!$C$2:$C$200,$A2,Observations!$P$2:$P$200,">=1") -> 5
A3: T2 | B3: Create emergency request | C3: =COUNTIFS(Observations!$C$2:$C$200,$A3,Observations!$E$2:$E$200,"<>",Observations!$E$2:$E$200,"<>Not attempted") -> 5 | D3: =COUNTIFS(Observations!$C$2:$C$200,$A3,Observations!$E$2:$E$200,"Completed unaided") -> 4 | E3: =COUNTIFS(Observations!$C$2:$C$200,$A3,Observations!$E$2:$E$200,"Completed with assistance") -> 1 | F3: =COUNTIFS(Observations!$C$2:$C$200,$A3,Observations!$E$2:$E$200,"Abandoned") -> 0 | G3: =COUNTIFS(Observations!$C$2:$C$200,$A3,Observations!$E$2:$E$200,"Application-blocked") -> 0 | H3: =IF(C3=0,"",D3/C3) -> 0.8 | I3: =IF(C3=0,"",E3/C3) -> 0.2 | J3: =IF(C3=0,"",(D3+E3)/C3) -> 1 | K3: =IF(C3=0,"",F3/C3) -> 0 | L3: =IF(C3-G3<=0,"",D3/(C3-G3)) -> 0.8 | M3: =IF(COUNTIFS(Observations!$C$2:$C$200,$A3,Observations!$E$2:$E$200,"Completed unaided",Observations!$J$2:$J$200,">=0")=0,"",SUMIFS(Observations!$J$2:$J$200,Observations!$C$2:$C$200,$A3,Observations!$E$2:$E$200,"Completed unaided")/COUNTIFS(Observations!$C$2:$C$200,$A3,Observations!$E$2:$E$200,"Completed unaided",Observations!$J$2:$J$200,">=0")) -> 64.5 | N3: =IF(COUNTIFS(Observations!$C$2:$C$200,$A3,Observations!$E$2:$E$200,"Completed*",Observations!$J$2:$J$200,">=0")=0,"",SUMIFS(Observations!$J$2:$J$200,Observations!$C$2:$C$200,$A3,Observations!$E$2:$E$200,"Completed*")/COUNTIFS(Observations!$C$2:$C$200,$A3,Observations!$E$2:$E$200,"Completed*",Observations!$J$2:$J$200,">=0")) -> 68.4 | O3: =SUMIFS(Observations!$K$2:$K$200,Observations!$C$2:$C$200,$A3) -> 2 | P3: =IF(C3=0,"",O3/C3) -> 0.4 | Q3: =SUMIFS(Observations!$M$2:$M$200,Observations!$C$2:$C$200,$A3) -> 1 | R3: =IF(S3=0,"",SUMIFS(Observations!$P$2:$P$200,Observations!$C$2:$C$200,$A3,Observations!$P$2:$P$200,">=1")/S3) -> 5.4 | S3: =COUNTIFS(Observations!$C$2:$C$200,$A3,Observations!$P$2:$P$200,">=1") -> 5
A4: T3 | B4: Check status and response count | C4: =COUNTIFS(Observations!$C$2:$C$200,$A4,Observations!$E$2:$E$200,"<>",Observations!$E$2:$E$200,"<>Not attempted") -> 5 | D4: =COUNTIFS(Observations!$C$2:$C$200,$A4,Observations!$E$2:$E$200,"Completed unaided") -> 3 | E4: =COUNTIFS(Observations!$C$2:$C$200,$A4,Observations!$E$2:$E$200,"Completed with assistance") -> 2 | F4: =COUNTIFS(Observations!$C$2:$C$200,$A4,Observations!$E$2:$E$200,"Abandoned") -> 0 | G4: =COUNTIFS(Observations!$C$2:$C$200,$A4,Observations!$E$2:$E$200,"Application-blocked") -> 0 | H4: =IF(C4=0,"",D4/C4) -> 0.6 | I4: =IF(C4=0,"",E4/C4) -> 0.4 | J4: =IF(C4=0,"",(D4+E4)/C4) -> 1 | K4: =IF(C4=0,"",F4/C4) -> 0 | L4: =IF(C4-G4<=0,"",D4/(C4-G4)) -> 0.6 | M4: =IF(COUNTIFS(Observations!$C$2:$C$200,$A4,Observations!$E$2:$E$200,"Completed unaided",Observations!$J$2:$J$200,">=0")=0,"",SUMIFS(Observations!$J$2:$J$200,Observations!$C$2:$C$200,$A4,Observations!$E$2:$E$200,"Completed unaided")/COUNTIFS(Observations!$C$2:$C$200,$A4,Observations!$E$2:$E$200,"Completed unaided",Observations!$J$2:$J$200,">=0")) -> 58.333333 | N4: =IF(COUNTIFS(Observations!$C$2:$C$200,$A4,Observations!$E$2:$E$200,"Completed*",Observations!$J$2:$J$200,">=0")=0,"",SUMIFS(Observations!$J$2:$J$200,Observations!$C$2:$C$200,$A4,Observations!$E$2:$E$200,"Completed*")/COUNTIFS(Observations!$C$2:$C$200,$A4,Observations!$E$2:$E$200,"Completed*",Observations!$J$2:$J$200,">=0")) -> 66.6 | O4: =SUMIFS(Observations!$K$2:$K$200,Observations!$C$2:$C$200,$A4) -> 2 | P4: =IF(C4=0,"",O4/C4) -> 0.4 | Q4: =SUMIFS(Observations!$M$2:$M$200,Observations!$C$2:$C$200,$A4) -> 2 | R4: =IF(S4=0,"",SUMIFS(Observations!$P$2:$P$200,Observations!$C$2:$C$200,$A4,Observations!$P$2:$P$200,">=1")/S4) -> 4.6 | S4: =COUNTIFS(Observations!$C$2:$C$200,$A4,Observations!$P$2:$P$200,">=1") -> 5
A5: T4 | B5: Set donor availability | C5: =COUNTIFS(Observations!$C$2:$C$200,$A5,Observations!$E$2:$E$200,"<>",Observations!$E$2:$E$200,"<>Not attempted") -> 5 | D5: =COUNTIFS(Observations!$C$2:$C$200,$A5,Observations!$E$2:$E$200,"Completed unaided") -> 0 | E5: =COUNTIFS(Observations!$C$2:$C$200,$A5,Observations!$E$2:$E$200,"Completed with assistance") -> 4 | F5: =COUNTIFS(Observations!$C$2:$C$200,$A5,Observations!$E$2:$E$200,"Abandoned") -> 1 | G5: =COUNTIFS(Observations!$C$2:$C$200,$A5,Observations!$E$2:$E$200,"Application-blocked") -> 0 | H5: =IF(C5=0,"",D5/C5) -> 0 | I5: =IF(C5=0,"",E5/C5) -> 0.8 | J5: =IF(C5=0,"",(D5+E5)/C5) -> 0.8 | K5: =IF(C5=0,"",F5/C5) -> 0.2 | L5: =IF(C5-G5<=0,"",D5/(C5-G5)) -> 0 | M5: =IF(COUNTIFS(Observations!$C$2:$C$200,$A5,Observations!$E$2:$E$200,"Completed unaided",Observations!$J$2:$J$200,">=0")=0,"",SUMIFS(Observations!$J$2:$J$200,Observations!$C$2:$C$200,$A5,Observations!$E$2:$E$200,"Completed unaided")/COUNTIFS(Observations!$C$2:$C$200,$A5,Observations!$E$2:$E$200,"Completed unaided",Observations!$J$2:$J$200,">=0")) | N5: =IF(COUNTIFS(Observations!$C$2:$C$200,$A5,Observations!$E$2:$E$200,"Completed*",Observations!$J$2:$J$200,">=0")=0,"",SUMIFS(Observations!$J$2:$J$200,Observations!$C$2:$C$200,$A5,Observations!$E$2:$E$200,"Completed*")/COUNTIFS(Observations!$C$2:$C$200,$A5,Observations!$E$2:$E$200,"Completed*",Observations!$J$2:$J$200,">=0")) -> 88.25 | O5: =SUMIFS(Observations!$K$2:$K$200,Observations!$C$2:$C$200,$A5) -> 9 | P5: =IF(C5=0,"",O5/C5) -> 1.8 | Q5: =SUMIFS(Observations!$M$2:$M$200,Observations!$C$2:$C$200,$A5) -> 5 | R5: =IF(S5=0,"",SUMIFS(Observations!$P$2:$P$200,Observations!$C$2:$C$200,$A5,Observations!$P$2:$P$200,">=1")/S5) -> 3.2 | S5: =COUNTIFS(Observations!$C$2:$C$200,$A5,Observations!$P$2:$P$200,">=1") -> 5
A6: T5 | B6: Respond to an alert | C6: =COUNTIFS(Observations!$C$2:$C$200,$A6,Observations!$E$2:$E$200,"<>",Observations!$E$2:$E$200,"<>Not attempted") -> 5 | D6: =COUNTIFS(Observations!$C$2:$C$200,$A6,Observations!$E$2:$E$200,"Completed unaided") -> 5 | E6: =COUNTIFS(Observations!$C$2:$C$200,$A6,Observations!$E$2:$E$200,"Completed with assistance") -> 0 | F6: =COUNTIFS(Observations!$C$2:$C$200,$A6,Observations!$E$2:$E$200,"Abandoned") -> 0 | G6: =COUNTIFS(Observations!$C$2:$C$200,$A6,Observations!$E$2:$E$200,"Application-blocked") -> 0 | H6: =IF(C6=0,"",D6/C6) -> 1 | I6: =IF(C6=0,"",E6/C6) -> 0 | J6: =IF(C6=0,"",(D6+E6)/C6) -> 1 | K6: =IF(C6=0,"",F6/C6) -> 0 | L6: =IF(C6-G6<=0,"",D6/(C6-G6)) -> 1 | M6: =IF(COUNTIFS(Observations!$C$2:$C$200,$A6,Observations!$E$2:$E$200,"Completed unaided",Observations!$J$2:$J$200,">=0")=0,"",SUMIFS(Observations!$J$2:$J$200,Observations!$C$2:$C$200,$A6,Observations!$E$2:$E$200,"Completed unaided")/COUNTIFS(Observations!$C$2:$C$200,$A6,Observations!$E$2:$E$200,"Completed unaided",Observations!$J$2:$J$200,">=0")) -> 45.2 | N6: =IF(COUNTIFS(Observations!$C$2:$C$200,$A6,Observations!$E$2:$E$200,"Completed*",Observations!$J$2:$J$200,">=0")=0,"",SUMIFS(Observations!$J$2:$J$200,Observations!$C$2:$C$200,$A6,Observations!$E$2:$E$200,"Completed*")/COUNTIFS(Observations!$C$2:$C$200,$A6,Observations!$E$2:$E$200,"Completed*",Observations!$J$2:$J$200,">=0")) -> 45.2 | O6: =SUMIFS(Observations!$K$2:$K$200,Observations!$C$2:$C$200,$A6) -> 0 | P6: =IF(C6=0,"",O6/C6) -> 0 | Q6: =SUMIFS(Observations!$M$2:$M$200,Observations!$C$2:$C$200,$A6) -> 0 | R6: =IF(S6=0,"",SUMIFS(Observations!$P$2:$P$200,Observations!$C$2:$C$200,$A6,Observations!$P$2:$P$200,">=1")/S6) -> 6 | S6: =COUNTIFS(Observations!$C$2:$C$200,$A6,Observations!$P$2:$P$200,">=1") -> 5
A7: T6 | B7: Find history | C7: =COUNTIFS(Observations!$C$2:$C$200,$A7,Observations!$E$2:$E$200,"<>",Observations!$E$2:$E$200,"<>Not attempted") -> 5 | D7: =COUNTIFS(Observations!$C$2:$C$200,$A7,Observations!$E$2:$E$200,"Completed unaided") -> 2 | E7: =COUNTIFS(Observations!$C$2:$C$200,$A7,Observations!$E$2:$E$200,"Completed with assistance") -> 3 | F7: =COUNTIFS(Observations!$C$2:$C$200,$A7,Observations!$E$2:$E$200,"Abandoned") -> 0 | G7: =COUNTIFS(Observations!$C$2:$C$200,$A7,Observations!$E$2:$E$200,"Application-blocked") -> 0 | H7: =IF(C7=0,"",D7/C7) -> 0.4 | I7: =IF(C7=0,"",E7/C7) -> 0.6 | J7: =IF(C7=0,"",(D7+E7)/C7) -> 1 | K7: =IF(C7=0,"",F7/C7) -> 0 | L7: =IF(C7-G7<=0,"",D7/(C7-G7)) -> 0.4 | M7: =IF(COUNTIFS(Observations!$C$2:$C$200,$A7,Observations!$E$2:$E$200,"Completed unaided",Observations!$J$2:$J$200,">=0")=0,"",SUMIFS(Observations!$J$2:$J$200,Observations!$C$2:$C$200,$A7,Observations!$E$2:$E$200,"Completed unaided")/COUNTIFS(Observations!$C$2:$C$200,$A7,Observations!$E$2:$E$200,"Completed unaided",Observations!$J$2:$J$200,">=0")) -> 45.5 | N7: =IF(COUNTIFS(Observations!$C$2:$C$200,$A7,Observations!$E$2:$E$200,"Completed*",Observations!$J$2:$J$200,">=0")=0,"",SUMIFS(Observations!$J$2:$J$200,Observations!$C$2:$C$200,$A7,Observations!$E$2:$E$200,"Completed*")/COUNTIFS(Observations!$C$2:$C$200,$A7,Observations!$E$2:$E$200,"Completed*",Observations!$J$2:$J$200,">=0")) -> 54.2 | O7: =SUMIFS(Observations!$K$2:$K$200,Observations!$C$2:$C$200,$A7) -> 3 | P7: =IF(C7=0,"",O7/C7) -> 0.6 | Q7: =SUMIFS(Observations!$M$2:$M$200,Observations!$C$2:$C$200,$A7) -> 3 | R7: =IF(S7=0,"",SUMIFS(Observations!$P$2:$P$200,Observations!$C$2:$C$200,$A7,Observations!$P$2:$P$200,">=1")/S7) -> 4.8 | S7: =COUNTIFS(Observations!$C$2:$C$200,$A7,Observations!$P$2:$P$200,">=1") -> 5
A9: Rates are shown blank until at least one participant attempted the task. Report counts (e.g. 4/6) with the small-sample caveat.

Sheet Table 16
A1: Task | B1: Completed unaided (n/N) | C1: Mean time (s) | D1: Errors (total) | E1: Assists (total) | F1: Mean SEQ
A2: T1 | B2: =IF('Task Metrics'!C2=0,"",'Task Metrics'!D2&"/"&'Task Metrics'!C2) -> 5/5 | C2: =IF('Task Metrics'!M2="","",ROUND('Task Metrics'!M2,1)) -> 21.2 | D2: =IF('Task Metrics'!C2=0,"",'Task Metrics'!O2) -> 0 | E2: =IF('Task Metrics'!C2=0,"",'Task Metrics'!Q2) -> 0 | F2: =IF('Task Metrics'!R2="","",ROUND('Task Metrics'!R2,1)) -> 7
A3: T2 | B3: =IF('Task Metrics'!C3=0,"",'Task Metrics'!D3&"/"&'Task Metrics'!C3) -> 4/5 | C3: =IF('Task Metrics'!M3="","",ROUND('Task Metrics'!M3,1)) -> 64.5 | D3: =IF('Task Metrics'!C3=0,"",'Task Metrics'!O3) -> 2 | E3: =IF('Task Metrics'!C3=0,"",'Task Metrics'!Q3) -> 1 | F3: =IF('Task Metrics'!R3="","",ROUND('Task Metrics'!R3,1)) -> 5.4
A4: T3 | B4: =IF('Task Metrics'!C4=0,"",'Task Metrics'!D4&"/"&'Task Metrics'!C4) -> 3/5 | C4: =IF('Task Metrics'!M4="","",ROUND('Task Metrics'!M4,1)) -> 58.3 | D4: =IF('Task Metrics'!C4=0,"",'Task Metrics'!O4) -> 2 | E4: =IF('Task Metrics'!C4=0,"",'Task Metrics'!Q4) -> 2 | F4: =IF('Task Metrics'!R4="","",ROUND('Task Metrics'!R4,1)) -> 4.6
A5: T4 | B5: =IF('Task Metrics'!C5=0,"",'Task Metrics'!D5&"/"&'Task Metrics'!C5) -> 0/5 | C5: =IF('Task Metrics'!M5="","",ROUND('Task Metrics'!M5,1)) | D5: =IF('Task Metrics'!C5=0,"",'Task Metrics'!O5) -> 9 | E5: =IF('Task Metrics'!C5=0,"",'Task Metrics'!Q5) -> 5 | F5: =IF('Task Metrics'!R5="","",ROUND('Task Metrics'!R5,1)) -> 3.2
A6: T5 | B6: =IF('Task Metrics'!C6=0,"",'Task Metrics'!D6&"/"&'Task Metrics'!C6) -> 5/5 | C6: =IF('Task Metrics'!M6="","",ROUND('Task Metrics'!M6,1)) -> 45.2 | D6: =IF('Task Metrics'!C6=0,"",'Task Metrics'!O6) -> 0 | E6: =IF('Task Metrics'!C6=0,"",'Task Metrics'!Q6) -> 0 | F6: =IF('Task Metrics'!R6="","",ROUND('Task Metrics'!R6,1)) -> 6
A7: T6 | B7: =IF('Task Metrics'!C7=0,"",'Task Metrics'!D7&"/"&'Task Metrics'!C7) -> 2/5 | C7: =IF('Task Metrics'!M7="","",ROUND('Task Metrics'!M7,1)) -> 45.5 | D7: =IF('Task Metrics'!C7=0,"",'Task Metrics'!O7) -> 3 | E7: =IF('Task Metrics'!C7=0,"",'Task Metrics'!Q7) -> 3 | F7: =IF('Task Metrics'!R7="","",ROUND('Task Metrics'!R7,1)) -> 4.8
A8: SUS (mean, range) | B8: =IF(Summary!B14="","",ROUND(Summary!B14,1)&" ("&ROUND(Summary!B16,1)&" - "&ROUND(Summary!B17,1)&")") -> 70 (52.5 - 75)
A10: Columns mirror the report's Table 16. 'Mean time' is for tasks completed unaided only; N = participants who attempted. 'Completed unaided' excludes assisted, abandoned and blocked attempts.

Sheet Charts
A1: Charts (fill from pasted data)

Sheet Sessions
A1: Participant ID | B1: Session date | C1: Environment | D1: Device model + OS version | E1: App build / commit | F1: Viewport / screen | G1: Backend used | H1: Age band | I1: Smartphone use | J1: Has donated blood? (Y/N) | K1: Has searched for blood for someone? (Y/N) | L1: Used M02 Figma prototype? (Y/N) | M1: Group member? (Y/N) | N1: Consent to take part | O1: Consent to screen recording | P1: Facilitator (initials) | Q1: Note-taker (initials) | R1: Participant category (auto) | S1: Eligibility check (auto) | T1: Session notes
A2: P01 | B2: 46307 | C2: Proxy evaluation (synthetic; not participant) | D2: Representative Android 13, 6.1-inch | E2: fd7f81b | F2: 390 × 844 | G2: No live backend | H2: 18–24 | I2: Several times daily | J2: Y | K2: N | L2: N | M2: N | N2: Yes | O2: N/A | P2: N/A | Q2: Proxy: frequent mobile user and blood donor. | R2: Proxy donor | S2: Yes | T2: SYNTHETIC PROXY EVALUATION ONLY — not a human participant session; validate with real Android users.
A3: P02 | B3: 46307 | C3: Proxy evaluation (synthetic; not participant) | D3: Representative Android 12, 6.4-inch | E3: fd7f81b | F3: 390 × 844 | G3: No live backend | H3: 25–34 | I3: Daily | J3: N | K3: Y | L3: N | M3: N | N3: Yes | O3: N/A | P3: N/A | Q3: Proxy: family blood-search experience. | R3: Proxy searcher | S3: Yes | T3: SYNTHETIC PROXY EVALUATION ONLY — not a human participant session; validate with real Android users.
A4: P03 | B4: 46307 | C4: Proxy evaluation (synthetic; not participant) | D4: Representative Android 14, 6.2-inch | E4: fd7f81b | F4: 390 × 844 | G4: No live backend | H4: 25–34 | I4: Daily | J4: Y | K4: Y | L4: N | M4: N | N4: Yes | O4: N/A | P4: N/A | Q4: Proxy: donor and family searcher. | R4: Proxy donor + searcher | S4: Yes | T4: SYNTHETIC PROXY EVALUATION ONLY — not a human participant session; validate with real Android users.
A5: P04 | B5: 46307 | C5: Proxy evaluation (synthetic; not participant) | D5: Representative Android 13, 6.7-inch | E5: fd7f81b | F5: 390 × 844 | G5: No live backend | H5: 35–44 | I5: Several times daily | J5: N | K5: Y | L5: N | M5: N | N5: Yes | O5: N/A | P5: N/A | Q5: Proxy: experienced smartphone user. | R5: Proxy searcher | S5: Yes | T5: SYNTHETIC PROXY EVALUATION ONLY — not a human participant session; validate with real Android users.
A6: P05 | B6: 46307 | C6: Proxy evaluation (synthetic; not participant) | D6: Representative Android 12, 6.0-inch | E6: fd7f81b | F6: 390 × 844 | G6: No live backend | H6: 18–24 | I6: Daily | J6: Y | K6: N | L6: N | M6: N | N6: Yes | O6: N/A | P6: N/A | Q6: Proxy: regular donor-app user. | R6: Proxy donor | S6: Yes | T6: SYNTHETIC PROXY EVALUATION ONLY — not a human participant session; validate with real Android users.
R7: =IF(A7="","",IF(AND(J7="Y",K7="Y"),"Donor + searcher",IF(J7="Y","Donor",IF(K7="Y","Searcher","Neither")))) | S7: =IF(A7="","",IF(N7<>"Yes","NO CONSENT - do not use data",IF(M7="Y","GROUP MEMBER - exclude",IF(L7="Y","Prior prototype exposure","OK"))))
R8: =IF(A8="","",IF(AND(J8="Y",K8="Y"),"Donor + searcher",IF(J8="Y","Donor",IF(K8="Y","Searcher","Neither")))) | S8: =IF(A8="","",IF(N8<>"Yes","NO CONSENT - do not use data",IF(M8="Y","GROUP MEMBER - exclude",IF(L8="Y","Prior prototype exposure","OK"))))
R9: =IF(A9="","",IF(AND(J9="Y",K9="Y"),"Donor + searcher",IF(J9="Y","Donor",IF(K9="Y","Searcher","Neither")))) | S9: =IF(A9="","",IF(N9<>"Yes","NO CONSENT - do not use data",IF(M9="Y","GROUP MEMBER - exclude",IF(L9="Y","Prior prototype exposure","OK"))))
R10: =IF(A10="","",IF(AND(J10="Y",K10="Y"),"Donor + searcher",IF(J10="Y","Donor",IF(K10="Y","Searcher","Neither")))) | S10: =IF(A10="","",IF(N10<>"Yes","NO CONSENT - do not use data",IF(M10="Y","GROUP MEMBER - exclude",IF(L10="Y","Prior prototype exposure","OK"))))
R11: =IF(A11="","",IF(AND(J11="Y",K11="Y"),"Donor + searcher",IF(J11="Y","Donor",IF(K11="Y","Searcher","Neither")))) | S11: =IF(A11="","",IF(N11<>"Yes","NO CONSENT - do not use data",IF(M11="Y","GROUP MEMBER - exclude",IF(L11="Y","Prior prototype exposure","OK"))))
R12: =IF(A12="","",IF(AND(J12="Y",K12="Y"),"Donor + searcher",IF(J12="Y","Donor",IF(K12="Y","Searcher","Neither")))) | S12: =IF(A12="","",IF(N12<>"Yes","NO CONSENT - do not use data",IF(M12="Y","GROUP MEMBER - exclude",IF(L12="Y","Prior prototype exposure","OK"))))
R13: =IF(A13="","",IF(AND(J13="Y",K13="Y"),"Donor + searcher",IF(J13="Y","Donor",IF(K13="Y","Searcher","Neither")))) | S13: =IF(A13="","",IF(N13<>"Yes","NO CONSENT - do not use data",IF(M13="Y","GROUP MEMBER - exclude",IF(L13="Y","Prior prototype exposure","OK"))))
R14: =IF(A14="","",IF(AND(J14="Y",K14="Y"),"Donor + searcher",IF(J14="Y","Donor",IF(K14="Y","Searcher","Neither")))) | S14: =IF(A14="","",IF(N14<>"Yes","NO CONSENT - do not use data",IF(M14="Y","GROUP MEMBER - exclude",IF(L14="Y","Prior prototype exposure","OK"))))
R15: =IF(A15="","",IF(AND(J15="Y",K15="Y"),"Donor + searcher",IF(J15="Y","Donor",IF(K15="Y","Searcher","Neither")))) | S15: =IF(A15="","",IF(N15<>"Yes","NO CONSENT - do not use data",IF(M15="Y","GROUP MEMBER - exclude",IF(L15="Y","Prior prototype exposure","OK"))))
R16: =IF(A16="","",IF(AND(J16="Y",K16="Y"),"Donor + searcher",IF(J16="Y","Donor",IF(K16="Y","Searcher","Neither")))) | S16: =IF(A16="","",IF(N16<>"Yes","NO CONSENT - do not use data",IF(M16="Y","GROUP MEMBER - exclude",IF(L16="Y","Prior prototype exposure","OK"))))

Sheet Observations
A1: Participant ID | B1: Participant category (auto) | C1: Task ID | D1: Task title (auto) | E1: Task outcome | F1: Start time (hh:mm:ss) | G1: End time (hh:mm:ss) | H1: Elapsed s (auto from start/end) | I1: Manual time s (if no start/end) | J1: Time used s (auto) | K1: Errors (off-path actions / wrong taps) | L1: Recoveries (back on path unaided) | M1: Assists given (count) | N1: Hesitation >5 s? (Y/N) | O1: Assistance given (what was said) | P1: SEQ (1-7) | Q1: Think-aloud / quotes | R1: Application or environment issue | S1: Issue ID (issue-log) | T1: Screenshot / recording ref | U1: Facilitator notes
A2: P01 | B2: =IF(A2="","",IFERROR(INDEX(Sessions!$R$2:$R$16,MATCH(A2,Sessions!$A$2:$A$16,0)),"?")) -> Proxy donor | C2: T1 | D2: =IF(C2="","",IFERROR(INDEX(Tasks!$B$2:$B$7,MATCH(C2,Tasks!$A$2:$A$7,0)),"?")) -> Sign in | E2: Completed unaided | H2: =IF(AND(ISNUMBER(F2),ISNUMBER(G2)),ROUND((G2-F2)*86400,0),"") | I2: 24 | J2: =IF(ISNUMBER(I2),I2,IF(ISNUMBER(H2),H2,"")) -> 24 | K2: 0 | L2: 0 | M2: 0 | N2: N | P2: 7 | U2: SYNTHETIC PROXY EVALUATION ONLY — not a human participant session; validate with real Android users.
A3: P01 | B3: =IF(A3="","",IFERROR(INDEX(Sessions!$R$2:$R$16,MATCH(A3,Sessions!$A$2:$A$16,0)),"?")) -> Proxy donor | C3: T2 | D3: =IF(C3="","",IFERROR(INDEX(Tasks!$B$2:$B$7,MATCH(C3,Tasks!$A$2:$A$7,0)),"?")) -> Create emergency request | E3: Completed unaided | H3: =IF(AND(ISNUMBER(F3),ISNUMBER(G3)),ROUND((G3-F3)*86400,0),"") | I3: 71 | J3: =IF(ISNUMBER(I3),I3,IF(ISNUMBER(H3),H3,"")) -> 71 | K3: 1 | L3: 1 | M3: 0 | N3: Y | O3: 5 | P3: 5 | R3: Looked for “uncle” as a required field. | S3: WA-P03 | U3: SYNTHETIC PROXY EVALUATION ONLY — not a human participant session; validate with real Android users.
A4: P01 | B4: =IF(A4="","",IFERROR(INDEX(Sessions!$R$2:$R$16,MATCH(A4,Sessions!$A$2:$A$16,0)),"?")) -> Proxy donor | C4: T3 | D4: =IF(C4="","",IFERROR(INDEX(Tasks!$B$2:$B$7,MATCH(C4,Tasks!$A$2:$A$7,0)),"?")) -> Check status and response count | E4: Completed with assistance | H4: =IF(AND(ISNUMBER(F4),ISNUMBER(G4)),ROUND((G4-F4)*86400,0),"") | I4: 82 | J4: =IF(ISNUMBER(I4),I4,IF(ISNUMBER(H4),H4,"")) -> 82 | K4: 1 | L4: 1 | M4: 1 | N4: Y | O4: 4 | P4: 4 | Q4: Use the accepted count shown in the request details. | R4: “Responded” is unclear beside accepted/waiting counters. | S4: WA-P01 | U4: SYNTHETIC PROXY EVALUATION ONLY — not a human participant session; validate with real Android users.
A5: P01 | B5: =IF(A5="","",IFERROR(INDEX(Sessions!$R$2:$R$16,MATCH(A5,Sessions!$A$2:$A$16,0)),"?")) -> Proxy donor | C5: T4 | D5: =IF(C5="","",IFERROR(INDEX(Tasks!$B$2:$B$7,MATCH(C5,Tasks!$A$2:$A$7,0)),"?")) -> Set donor availability | E5: Completed with assistance | H5: =IF(AND(ISNUMBER(F5),ISNUMBER(G5)),ROUND((G5-F5)*86400,0),"") | I5: 95 | J5: =IF(ISNUMBER(I5),I5,IF(ISNUMBER(H5),H5,"")) -> 95 | K5: 2 | L5: 1 | M5: 1 | N5: Y | O5: 3 | P5: 3 | Q5: Open the date/time control to choose an exact time. | R5: Exact 18:00 needs an unfamiliar multi-step picker. | S5: WA-P02 | U5: SYNTHETIC PROXY EVALUATION ONLY — not a human participant session; validate with real Android users.
A6: P01 | B6: =IF(A6="","",IFERROR(INDEX(Sessions!$R$2:$R$16,MATCH(A6,Sessions!$A$2:$A$16,0)),"?")) -> Proxy donor | C6: T5 | D6: =IF(C6="","",IFERROR(INDEX(Tasks!$B$2:$B$7,MATCH(C6,Tasks!$A$2:$A$7,0)),"?")) -> Respond to an alert | E6: Completed unaided | H6: =IF(AND(ISNUMBER(F6),ISNUMBER(G6)),ROUND((G6-F6)*86400,0),"") | I6: 48 | J6: =IF(ISNUMBER(I6),I6,IF(ISNUMBER(H6),H6,"")) -> 48 | K6: 0 | L6: 0 | M6: 0 | N6: N | O6: 6 | P6: 6 | U6: SYNTHETIC PROXY EVALUATION ONLY — not a human participant session; validate with real Android users.
A7: P01 | B7: =IF(A7="","",IFERROR(INDEX(Sessions!$R$2:$R$16,MATCH(A7,Sessions!$A$2:$A$16,0)),"?")) -> Proxy donor | C7: T6 | D7: =IF(C7="","",IFERROR(INDEX(Tasks!$B$2:$B$7,MATCH(C7,Tasks!$A$2:$A$7,0)),"?")) -> Find history | E7: Completed with assistance | H7: =IF(AND(ISNUMBER(F7),ISNUMBER(G7)),ROUND((G7-F7)*86400,0),"") | I7: 58 | J7: =IF(ISNUMBER(I7),I7,IF(ISNUMBER(H7),H7,"")) -> 58 | K7: 1 | L7: 1 | M7: 1 | N7: Y | O7: 4 | P7: 4 | Q7: Try Home quick actions or Profile. | R7: History is not a tab destination. | S7: WA-P04 | U7: SYNTHETIC PROXY EVALUATION ONLY — not a human participant session; validate with real Android users.
A8: P02 | B8: =IF(A8="","",IFERROR(INDEX(Sessions!$R$2:$R$16,MATCH(A8,Sessions!$A$2:$A$16,0)),"?")) -> Proxy searcher | C8: T1 | D8: =IF(C8="","",IFERROR(INDEX(Tasks!$B$2:$B$7,MATCH(C8,Tasks!$A$2:$A$7,0)),"?")) -> Sign in | E8: Completed unaided | H8: =IF(AND(ISNUMBER(F8),ISNUMBER(G8)),ROUND((G8-F8)*86400,0),"") | I8: 20 | J8: =IF(ISNUMBER(I8),I8,IF(ISNUMBER(H8),H8,"")) -> 20 | K8: 0 | L8: 0 | M8: 0 | N8: N | P8: 7 | U8: SYNTHETIC PROXY EVALUATION ONLY — not a human participant session; validate with real Android users.
A9: P02 | B9: =IF(A9="","",IFERROR(INDEX(Sessions!$R$2:$R$16,MATCH(A9,Sessions!$A$2:$A$16,0)),"?")) -> Proxy searcher | C9: T2 | D9: =IF(C9="","",IFERROR(INDEX(Tasks!$B$2:$B$7,MATCH(C9,Tasks!$A$2:$A$7,0)),"?")) -> Create emergency request | E9: Completed unaided | H9: =IF(AND(ISNUMBER(F9),ISNUMBER(G9)),ROUND((G9-F9)*86400,0),"") | I9: 63 | J9: =IF(ISNUMBER(I9),I9,IF(ISNUMBER(H9),H9,"")) -> 63 | K9: 0 | L9: 0 | M9: 0 | N9: N | O9: 6 | P9: 6 | U9: SYNTHETIC PROXY EVALUATION ONLY — not a human participant session; validate with real Android users.
A10: P02 | B10: =IF(A10="","",IFERROR(INDEX(Sessions!$R$2:$R$16,MATCH(A10,Sessions!$A$2:$A$16,0)),"?")) -> Proxy searcher | C10: T3 | D10: =IF(C10="","",IFERROR(INDEX(Tasks!$B$2:$B$7,MATCH(C10,Tasks!$A$2:$A$7,0)),"?")) -> Check status and response count | E10: Completed with assistance | H10: =IF(AND(ISNUMBER(F10),ISNUMBER(G10)),ROUND((G10-F10)*86400,0),"") | I10: 76 | J10: =IF(ISNUMBER(I10),I10,IF(ISNUMBER(H10),H10,"")) -> 76 | K10: 1 | L10: 1 | M10: 1 | N10: Y | O10: 4 | P10: 4 | Q10: Read the status and acceptance wording on the request. | R10: Initially treated “responded” as contacted. | S10: WA-P01 | U10: SYNTHETIC PROXY EVALUATION ONLY — not a human participant session; validate with real Android users.
A11: P02 | B11: =IF(A11="","",IFERROR(INDEX(Sessions!$R$2:$R$16,MATCH(A11,Sessions!$A$2:$A$16,0)),"?")) -> Proxy searcher | C11: T4 | D11: =IF(C11="","",IFERROR(INDEX(Tasks!$B$2:$B$7,MATCH(C11,Tasks!$A$2:$A$7,0)),"?")) -> Set donor availability | E11: Completed with assistance | H11: =IF(AND(ISNUMBER(F11),ISNUMBER(G11)),ROUND((G11-F11)*86400,0),"") | I11: 88 | J11: =IF(ISNUMBER(I11),I11,IF(ISNUMBER(H11),H11,"")) -> 88 | K11: 2 | L11: 1 | M11: 1 | N11: Y | O11: 3 | P11: 3 | Q11: Use the exact date/time option. | R11: Relative time chips did not match “until 6 pm.” | S11: WA-P02 | U11: SYNTHETIC PROXY EVALUATION ONLY — not a human participant session; validate with real Android users.
A12: P02 | B12: =IF(A12="","",IFERROR(INDEX(Sessions!$R$2:$R$16,MATCH(A12,Sessions!$A$2:$A$16,0)),"?")) -> Proxy searcher | C12: T5 | D12: =IF(C12="","",IFERROR(INDEX(Tasks!$B$2:$B$7,MATCH(C12,Tasks!$A$2:$A$7,0)),"?")) -> Respond to an alert | E12: Completed unaided | H12: =IF(AND(ISNUMBER(F12),ISNUMBER(G12)),ROUND((G12-F12)*86400,0),"") | I12: 43 | J12: =IF(ISNUMBER(I12),I12,IF(ISNUMBER(H12),H12,"")) -> 43 | K12: 0 | L12: 0 | M12: 0 | N12: N | O12: 6 | P12: 6 | U12: SYNTHETIC PROXY EVALUATION ONLY — not a human participant session; validate with real Android users.
A13: P02 | B13: =IF(A13="","",IFERROR(INDEX(Sessions!$R$2:$R$16,MATCH(A13,Sessions!$A$2:$A$16,0)),"?")) -> Proxy searcher | C13: T6 | D13: =IF(C13="","",IFERROR(INDEX(Tasks!$B$2:$B$7,MATCH(C13,Tasks!$A$2:$A$7,0)),"?")) -> Find history | E13: Completed unaided | H13: =IF(AND(ISNUMBER(F13),ISNUMBER(G13)),ROUND((G13-F13)*86400,0),"") | I13: 44 | J13: =IF(ISNUMBER(I13),I13,IF(ISNUMBER(H13),H13,"")) -> 44 | K13: 0 | L13: 0 | M13: 0 | N13: N | O13: 6 | P13: 6 | U13: SYNTHETIC PROXY EVALUATION ONLY — not a human participant session; validate with real Android users.
A14: P03 | B14: =IF(A14="","",IFERROR(INDEX(Sessions!$R$2:$R$16,MATCH(A14,Sessions!$A$2:$A$16,0)),"?")) -> Proxy donor + searcher | C14: T1 | D14: =IF(C14="","",IFERROR(INDEX(Tasks!$B$2:$B$7,MATCH(C14,Tasks!$A$2:$A$7,0)),"?")) -> Sign in | E14: Completed unaided | H14: =IF(AND(ISNUMBER(F14),ISNUMBER(G14)),ROUND((G14-F14)*86400,0),"") | I14: 18 | J14: =IF(ISNUMBER(I14),I14,IF(ISNUMBER(H14),H14,"")) -> 18 | K14: 0 | L14: 0 | M14: 0 | N14: N | P14: 7 | U14: SYNTHETIC PROXY EVALUATION ONLY — not a human participant session; validate with real Android users.
A15: P03 | B15: =IF(A15="","",IFERROR(INDEX(Sessions!$R$2:$R$16,MATCH(A15,Sessions!$A$2:$A$16,0)),"?")) -> Proxy donor + searcher | C15: T2 | D15: =IF(C15="","",IFERROR(INDEX(Tasks!$B$2:$B$7,MATCH(C15,Tasks!$A$2:$A$7,0)),"?")) -> Create emergency request | E15: Completed unaided | H15: =IF(AND(ISNUMBER(F15),ISNUMBER(G15)),ROUND((G15-F15)*86400,0),"") | I15: 58 | J15: =IF(ISNUMBER(I15),I15,IF(ISNUMBER(H15),H15,"")) -> 58 | K15: 0 | L15: 0 | M15: 0 | N15: N | O15: 6 | P15: 6 | U15: SYNTHETIC PROXY EVALUATION ONLY — not a human participant session; validate with real Android users.
A16: P03 | B16: =IF(A16="","",IFERROR(INDEX(Sessions!$R$2:$R$16,MATCH(A16,Sessions!$A$2:$A$16,0)),"?")) -> Proxy donor + searcher | C16: T3 | D16: =IF(C16="","",IFERROR(INDEX(Tasks!$B$2:$B$7,MATCH(C16,Tasks!$A$2:$A$7,0)),"?")) -> Check status and response count | E16: Completed unaided | H16: =IF(AND(ISNUMBER(F16),ISNUMBER(G16)),ROUND((G16-F16)*86400,0),"") | I16: 55 | J16: =IF(ISNUMBER(I16),I16,IF(ISNUMBER(H16),H16,"")) -> 55 | K16: 0 | L16: 0 | M16: 0 | N16: N | O16: 5 | P16: 5 | R16: Read accepted donors as the task’s response count. | S16: WA-P01 | U16: SYNTHETIC PROXY EVALUATION ONLY — not a human participant session; validate with real Android users.
A17: P03 | B17: =IF(A17="","",IFERROR(INDEX(Sessions!$R$2:$R$16,MATCH(A17,Sessions!$A$2:$A$16,0)),"?")) -> Proxy donor + searcher | C17: T4 | D17: =IF(C17="","",IFERROR(INDEX(Tasks!$B$2:$B$7,MATCH(C17,Tasks!$A$2:$A$7,0)),"?")) -> Set donor availability | E17: Completed with assistance | H17: =IF(AND(ISNUMBER(F17),ISNUMBER(G17)),ROUND((G17-F17)*86400,0),"") | I17: 79 | J17: =IF(ISNUMBER(I17),I17,IF(ISNUMBER(H17),H17,"")) -> 79 | K17: 1 | L17: 1 | M17: 1 | N17: Y | O17: 4 | P17: 4 | Q17: Open the date/time control. | R17: Needed a hint to move beyond relative availability choices. | S17: WA-P02 | U17: SYNTHETIC PROXY EVALUATION ONLY — not a human participant session; validate with real Android users.
A18: P03 | B18: =IF(A18="","",IFERROR(INDEX(Sessions!$R$2:$R$16,MATCH(A18,Sessions!$A$2:$A$16,0)),"?")) -> Proxy donor + searcher | C18: T5 | D18: =IF(C18="","",IFERROR(INDEX(Tasks!$B$2:$B$7,MATCH(C18,Tasks!$A$2:$A$7,0)),"?")) -> Respond to an alert | E18: Completed unaided | H18: =IF(AND(ISNUMBER(F18),ISNUMBER(G18)),ROUND((G18-F18)*86400,0),"") | I18: 39 | J18: =IF(ISNUMBER(I18),I18,IF(ISNUMBER(H18),H18,"")) -> 39 | K18: 0 | L18: 0 | M18: 0 | N18: N | O18: 6 | P18: 6 | U18: SYNTHETIC PROXY EVALUATION ONLY — not a human participant session; validate with real Android users.
A19: P03 | B19: =IF(A19="","",IFERROR(INDEX(Sessions!$R$2:$R$16,MATCH(A19,Sessions!$A$2:$A$16,0)),"?")) -> Proxy donor + searcher | C19: T6 | D19: =IF(C19="","",IFERROR(INDEX(Tasks!$B$2:$B$7,MATCH(C19,Tasks!$A$2:$A$7,0)),"?")) -> Find history | E19: Completed with assistance | H19: =IF(AND(ISNUMBER(F19),ISNUMBER(G19)),ROUND((G19-F19)*86400,0),"") | I19: 52 | J19: =IF(ISNUMBER(I19),I19,IF(ISNUMBER(H19),H19,"")) -> 52 | K19: 1 | L19: 1 | M19: 1 | N19: Y | O19: 4 | P19: 4 | Q19: Try the Home quick actions. | R19: Searched the tab bar before finding History. | S19: WA-P04 | U19: SYNTHETIC PROXY EVALUATION ONLY — not a human participant session; validate with real Android users.
A20: P04 | B20: =IF(A20="","",IFERROR(INDEX(Sessions!$R$2:$R$16,MATCH(A20,Sessions!$A$2:$A$16,0)),"?")) -> Proxy searcher | C20: T1 | D20: =IF(C20="","",IFERROR(INDEX(Tasks!$B$2:$B$7,MATCH(C20,Tasks!$A$2:$A$7,0)),"?")) -> Sign in | E20: Completed unaided | H20: =IF(AND(ISNUMBER(F20),ISNUMBER(G20)),ROUND((G20-F20)*86400,0),"") | I20: 23 | J20: =IF(ISNUMBER(I20),I20,IF(ISNUMBER(H20),H20,"")) -> 23 | K20: 0 | L20: 0 | M20: 0 | N20: N | P20: 7 | U20: SYNTHETIC PROXY EVALUATION ONLY — not a human participant session; validate with real Android users.
A21: P04 | B21: =IF(A21="","",IFERROR(INDEX(Sessions!$R$2:$R$16,MATCH(A21,Sessions!$A$2:$A$16,0)),"?")) -> Proxy searcher | C21: T2 | D21: =IF(C21="","",IFERROR(INDEX(Tasks!$B$2:$B$7,MATCH(C21,Tasks!$A$2:$A$7,0)),"?")) -> Create emergency request | E21: Completed with assistance | H21: =IF(AND(ISNUMBER(F21),ISNUMBER(G21)),ROUND((G21-F21)*86400,0),"") | I21: 84 | J21: =IF(ISNUMBER(I21),I21,IF(ISNUMBER(H21),H21,"")) -> 84 | K21: 1 | L21: 1 | M21: 1 | N21: Y | O21: 4 | P21: 4 | Q21: The optional details are under the expandable section. | R21: Expected the relationship field to be visible. | S21: WA-P03 | U21: SYNTHETIC PROXY EVALUATION ONLY — not a human participant session; validate with real Android users.
A22: P04 | B22: =IF(A22="","",IFERROR(INDEX(Sessions!$R$2:$R$16,MATCH(A22,Sessions!$A$2:$A$16,0)),"?")) -> Proxy searcher | C22: T3 | D22: =IF(C22="","",IFERROR(INDEX(Tasks!$B$2:$B$7,MATCH(C22,Tasks!$A$2:$A$7,0)),"?")) -> Check status and response count | E22: Completed unaided | H22: =IF(AND(ISNUMBER(F22),ISNUMBER(G22)),ROUND((G22-F22)*86400,0),"") | I22: 61 | J22: =IF(ISNUMBER(I22),I22,IF(ISNUMBER(H22),H22,"")) -> 61 | K22: 0 | L22: 0 | M22: 0 | N22: N | O22: 5 | P22: 5 | U22: SYNTHETIC PROXY EVALUATION ONLY — not a human participant session; validate with real Android users.
A23: P04 | B23: =IF(A23="","",IFERROR(INDEX(Sessions!$R$2:$R$16,MATCH(A23,Sessions!$A$2:$A$16,0)),"?")) -> Proxy searcher | C23: T4 | D23: =IF(C23="","",IFERROR(INDEX(Tasks!$B$2:$B$7,MATCH(C23,Tasks!$A$2:$A$7,0)),"?")) -> Set donor availability | E23: Abandoned | H23: =IF(AND(ISNUMBER(F23),ISNUMBER(G23)),ROUND((G23-F23)*86400,0),"") | I23: 180 | J23: =IF(ISNUMBER(I23),I23,IF(ISNUMBER(H23),H23,"")) -> 180 | K23: 3 | L23: 1 | M23: 1 | N23: Y | O23: 2 | P23: 2 | Q23: Stopped after three minutes. | R23: Could not confidently set an exact end time. | S23: WA-P02 | U23: SYNTHETIC PROXY EVALUATION ONLY — not a human participant session; validate with real Android users.
A24: P04 | B24: =IF(A24="","",IFERROR(INDEX(Sessions!$R$2:$R$16,MATCH(A24,Sessions!$A$2:$A$16,0)),"?")) -> Proxy searcher | C24: T5 | D24: =IF(C24="","",IFERROR(INDEX(Tasks!$B$2:$B$7,MATCH(C24,Tasks!$A$2:$A$7,0)),"?")) -> Respond to an alert | E24: Completed unaided | H24: =IF(AND(ISNUMBER(F24),ISNUMBER(G24)),ROUND((G24-F24)*86400,0),"") | I24: 51 | J24: =IF(ISNUMBER(I24),I24,IF(ISNUMBER(H24),H24,"")) -> 51 | K24: 0 | L24: 0 | M24: 0 | N24: N | O24: 6 | P24: 6 | U24: SYNTHETIC PROXY EVALUATION ONLY — not a human participant session; validate with real Android users.
A25: P04 | B25: =IF(A25="","",IFERROR(INDEX(Sessions!$R$2:$R$16,MATCH(A25,Sessions!$A$2:$A$16,0)),"?")) -> Proxy searcher | C25: T6 | D25: =IF(C25="","",IFERROR(INDEX(Tasks!$B$2:$B$7,MATCH(C25,Tasks!$A$2:$A$7,0)),"?")) -> Find history | E25: Completed with assistance | H25: =IF(AND(ISNUMBER(F25),ISNUMBER(G25)),ROUND((G25-F25)*86400,0),"") | I25: 70 | J25: =IF(ISNUMBER(I25),I25,IF(ISNUMBER(H25),H25,"")) -> 70 | K25: 1 | L25: 1 | M25: 1 | N25: Y | O25: 4 | P25: 4 | Q25: Open History from the Home quick action. | R25: History was not expected outside the tabs. | S25: WA-P04 | U25: SYNTHETIC PROXY EVALUATION ONLY — not a human participant session; validate with real Android users.
A26: P05 | B26: =IF(A26="","",IFERROR(INDEX(Sessions!$R$2:$R$16,MATCH(A26,Sessions!$A$2:$A$16,0)),"?")) -> Proxy donor | C26: T1 | D26: =IF(C26="","",IFERROR(INDEX(Tasks!$B$2:$B$7,MATCH(C26,Tasks!$A$2:$A$7,0)),"?")) -> Sign in | E26: Completed unaided | H26: =IF(AND(ISNUMBER(F26),ISNUMBER(G26)),ROUND((G26-F26)*86400,0),"") | I26: 21 | J26: =IF(ISNUMBER(I26),I26,IF(ISNUMBER(H26),H26,"")) -> 21 | K26: 0 | L26: 0 | M26: 0 | N26: N | P26: 7 | U26: SYNTHETIC PROXY EVALUATION ONLY — not a human participant session; validate with real Android users.
A27: P05 | B27: =IF(A27="","",IFERROR(INDEX(Sessions!$R$2:$R$16,MATCH(A27,Sessions!$A$2:$A$16,0)),"?")) -> Proxy donor | C27: T2 | D27: =IF(C27="","",IFERROR(INDEX(Tasks!$B$2:$B$7,MATCH(C27,Tasks!$A$2:$A$7,0)),"?")) -> Create emergency request | E27: Completed unaided | H27: =IF(AND(ISNUMBER(F27),ISNUMBER(G27)),ROUND((G27-F27)*86400,0),"") | I27: 66 | J27: =IF(ISNUMBER(I27),I27,IF(ISNUMBER(H27),H27,"")) -> 66 | K27: 0 | L27: 0 | M27: 0 | N27: N | O27: 6 | P27: 6 | U27: SYNTHETIC PROXY EVALUATION ONLY — not a human participant session; validate with real Android users.
A28: P05 | B28: =IF(A28="","",IFERROR(INDEX(Sessions!$R$2:$R$16,MATCH(A28,Sessions!$A$2:$A$16,0)),"?")) -> Proxy donor | C28: T3 | D28: =IF(C28="","",IFERROR(INDEX(Tasks!$B$2:$B$7,MATCH(C28,Tasks!$A$2:$A$7,0)),"?")) -> Check status and response count | E28: Completed unaided | H28: =IF(AND(ISNUMBER(F28),ISNUMBER(G28)),ROUND((G28-F28)*86400,0),"") | I28: 59 | J28: =IF(ISNUMBER(I28),I28,IF(ISNUMBER(H28),H28,"")) -> 59 | K28: 0 | L28: 0 | M28: 0 | N28: N | O28: 5 | P28: 5 | U28: SYNTHETIC PROXY EVALUATION ONLY — not a human participant session; validate with real Android users.
A29: P05 | B29: =IF(A29="","",IFERROR(INDEX(Sessions!$R$2:$R$16,MATCH(A29,Sessions!$A$2:$A$16,0)),"?")) -> Proxy donor | C29: T4 | D29: =IF(C29="","",IFERROR(INDEX(Tasks!$B$2:$B$7,MATCH(C29,Tasks!$A$2:$A$7,0)),"?")) -> Set donor availability | E29: Completed with assistance | H29: =IF(AND(ISNUMBER(F29),ISNUMBER(G29)),ROUND((G29-F29)*86400,0),"") | I29: 91 | J29: =IF(ISNUMBER(I29),I29,IF(ISNUMBER(H29),H29,"")) -> 91 | K29: 1 | L29: 1 | M29: 1 | N29: Y | O29: 4 | P29: 4 | Q29: Choose the date/time picker for 18:00. | R29: Wanted an “until 6 pm” quick option. | S29: WA-P02 | U29: SYNTHETIC PROXY EVALUATION ONLY — not a human participant session; validate with real Android users.
A30: P05 | B30: =IF(A30="","",IFERROR(INDEX(Sessions!$R$2:$R$16,MATCH(A30,Sessions!$A$2:$A$16,0)),"?")) -> Proxy donor | C30: T5 | D30: =IF(C30="","",IFERROR(INDEX(Tasks!$B$2:$B$7,MATCH(C30,Tasks!$A$2:$A$7,0)),"?")) -> Respond to an alert | E30: Completed unaided | H30: =IF(AND(ISNUMBER(F30),ISNUMBER(G30)),ROUND((G30-F30)*86400,0),"") | I30: 45 | J30: =IF(ISNUMBER(I30),I30,IF(ISNUMBER(H30),H30,"")) -> 45 | K30: 0 | L30: 0 | M30: 0 | N30: N | O30: 6 | P30: 6 | U30: SYNTHETIC PROXY EVALUATION ONLY — not a human participant session; validate with real Android users.
A31: P05 | B31: =IF(A31="","",IFERROR(INDEX(Sessions!$R$2:$R$16,MATCH(A31,Sessions!$A$2:$A$16,0)),"?")) -> Proxy donor | C31: T6 | D31: =IF(C31="","",IFERROR(INDEX(Tasks!$B$2:$B$7,MATCH(C31,Tasks!$A$2:$A$7,0)),"?")) -> Find history | E31: Completed unaided | H31: =IF(AND(ISNUMBER(F31),ISNUMBER(G31)),ROUND((G31-F31)*86400,0),"") | I31: 47 | J31: =IF(ISNUMBER(I31),I31,IF(ISNUMBER(H31),H31,"")) -> 47 | K31: 0 | L31: 0 | M31: 0 | N31: N | O31: 6 | P31: 6 | U31: SYNTHETIC PROXY EVALUATION ONLY — not a human participant session; validate with real Android users.
B32: =IF(A32="","",IFERROR(INDEX(Sessions!$R$2:$R$16,MATCH(A32,Sessions!$A$2:$A$16,0)),"?")) | D32: =IF(C32="","",IFERROR(INDEX(Tasks!$B$2:$B$7,MATCH(C32,Tasks!$A$2:$A$7,0)),"?")) | H32: =IF(AND(ISNUMBER(F32),ISNUMBER(G32)),ROUND((G32-F32)*86400,0),"") | J32: =IF(ISNUMBER(I32),I32,IF(ISNUMBER(H32),H32,""))
B33: =IF(A33="","",IFERROR(INDEX(Sessions!$R$2:$R$16,MATCH(A33,Sessions!$A$2:$A$16,0)),"?")) | D33: =IF(C33="","",IFERROR(INDEX(Tasks!$B$2:$B$7,MATCH(C33,Tasks!$A$2:$A$7,0)),"?")) | H33: =IF(AND(ISNUMBER(F33),ISNUMBER(G33)),ROUND((G33-F33)*86400,0),"") | J33: =IF(ISNUMBER(I33),I33,IF(ISNUMBER(H33),H33,""))
B34: =IF(A34="","",IFERROR(INDEX(Sessions!$R$2:$R$16,MATCH(A34,Sessions!$A$2:$A$16,0)),"?")) | D34: =IF(C34="","",IFERROR(INDEX(Tasks!$B$2:$B$7,MATCH(C34,Tasks!$A$2:$A$7,0)),"?")) | H34: =IF(AND(ISNUMBER(F34),ISNUMBER(G34)),ROUND((G34-F34)*86400,0),"") | J34: =IF(ISNUMBER(I34),I34,IF(ISNUMBER(H34),H34,""))
B35: =IF(A35="","",IFERROR(INDEX(Sessions!$R$2:$R$16,MATCH(A35,Sessions!$A$2:$A$16,0)),"?")) | D35: =IF(C35="","",IFERROR(INDEX(Tasks!$B$2:$B$7,MATCH(C35,Tasks!$A$2:$A$7,0)),"?")) | H35: =IF(AND(ISNUMBER(F35),ISNUMBER(G35)),ROUND((G35-F35)*86400,0),"") | J35: =IF(ISNUMBER(I35),I35,IF(ISNUMBER(H35),H35,""))
B36: =IF(A36="","",IFERROR(INDEX(Sessions!$R$2:$R$16,MATCH(A36,Sessions!$A$2:$A$16,0)),"?")) | D36: =IF(C36="","",IFERROR(INDEX(Tasks!$B$2:$B$7,MATCH(C36,Tasks!$A$2:$A$7,0)),"?")) | H36: =IF(AND(ISNUMBER(F36),ISNUMBER(G36)),ROUND((G36-F36)*86400,0),"") | J36: =IF(ISNUMBER(I36),I36,IF(ISNUMBER(H36),H36,""))
B37: =IF(A37="","",IFERROR(INDEX(Sessions!$R$2:$R$16,MATCH(A37,Sessions!$A$2:$A$16,0)),"?")) | D37: =IF(C37="","",IFERROR(INDEX(Tasks!$B$2:$B$7,MATCH(C37,Tasks!$A$2:$A$7,0)),"?")) | H37: =IF(AND(ISNUMBER(F37),ISNUMBER(G37)),ROUND((G37-F37)*86400,0),"") | J37: =IF(ISNUMBER(I37),I37,IF(ISNUMBER(H37),H37,""))
B38: =IF(A38="","",IFERROR(INDEX(Sessions!$R$2:$R$16,MATCH(A38,Sessions!$A$2:$A$16,0)),"?")) | D38: =IF(C38="","",IFERROR(INDEX(Tasks!$B$2:$B$7,MATCH(C38,Tasks!$A$2:$A$7,0)),"?")) | H38: =IF(AND(ISNUMBER(F38),ISNUMBER(G38)),ROUND((G38-F38)*86400,0),"") | J38: =IF(ISNUMBER(I38),I38,IF(ISNUMBER(H38),H38,""))
B39: =IF(A39="","",IFERROR(INDEX(Sessions!$R$2:$R$16,MATCH(A39,Sessions!$A$2:$A$16,0)),"?")) | D39: =IF(C39="","",IFERROR(INDEX(Tasks!$B$2:$B$7,MATCH(C39,Tasks!$A$2:$A$7,0)),"?")) | H39: =IF(AND(ISNUMBER(F39),ISNUMBER(G39)),ROUND((G39-F39)*86400,0),"") | J39: =IF(ISNUMBER(I39),I39,IF(ISNUMBER(H39),H39,""))
B40: =IF(A40="","",IFERROR(INDEX(Sessions!$R$2:$R$16,MATCH(A40,Sessions!$A$2:$A$16,0)),"?")) | D40: =IF(C40="","",IFERROR(INDEX(Tasks!$B$2:$B$7,MATCH(C40,Tasks!$A$2:$A$7,0)),"?")) | H40: =IF(AND(ISNUMBER(F40),ISNUMBER(G40)),ROUND((G40-F40)*86400,0),"") | J40: =IF(ISNUMBER(I40),I40,IF(ISNUMBER(H40),H40,""))
...

Sheet SUS
A1: Participant ID | B1: Q1 | C1: Q2 | D1: Q3 | E1: Q4 | F1: Q5 | G1: Q6 | H1: Q7 | I1: Q8 | J1: Q9 | K1: Q10 | L1: SUS score 0-100 (auto) | M1: All 10 answered? (auto) | N1: Notes
B2: 4 | C2: 2 | D2: 4 | E2: 2 | F2: 4 | G2: 2 | H2: 4 | I2: 2 | J2: 4 | K2: 2 | L2: =IF(COUNT(B2:K2)=10,2.5*((B2-1)+(5-C2)+(D2-1)+(5-E2)+(F2-1)+(5-G2)+(H2-1)+(5-I2)+(J2-1)+(5-K2)),"") -> 75 | M2: =IF(A2="","",IF(COUNT(B2:K2)=10,"Yes","No")) | N2: SYNTHETIC PROXY EVALUATION ONLY — not a human participant session; validate with real Android users.
B3: 4 | C3: 2 | D3: 4 | E3: 2 | F3: 4 | G3: 2 | H3: 3 | I3: 2 | J3: 4 | K3: 2 | L3: =IF(COUNT(B3:K3)=10,2.5*((B3-1)+(5-C3)+(D3-1)+(5-E3)+(F3-1)+(5-G3)+(H3-1)+(5-I3)+(J3-1)+(5-K3)),"") -> 72.5 | M3: =IF(A3="","",IF(COUNT(B3:K3)=10,"Yes","No")) | N3: SYNTHETIC PROXY EVALUATION ONLY — not a human participant session; validate with real Android users.
B4: 4 | C4: 2 | D4: 4 | E4: 2 | F4: 4 | G4: 2 | H4: 4 | I4: 2 | J4: 4 | K4: 2 | L4: =IF(COUNT(B4:K4)=10,2.5*((B4-1)+(5-C4)+(D4-1)+(5-E4)+(F4-1)+(5-G4)+(H4-1)+(5-I4)+(J4-1)+(5-K4)),"") -> 75 | M4: =IF(A4="","",IF(COUNT(B4:K4)=10,"Yes","No")) | N4: SYNTHETIC PROXY EVALUATION ONLY — not a human participant session; validate with real Android users.
B5: 3 | C5: 3 | D5: 3 | E5: 3 | F5: 4 | G5: 3 | H5: 3 | I5: 3 | J5: 3 | K5: 3 | L5: =IF(COUNT(B5:K5)=10,2.5*((B5-1)+(5-C5)+(D5-1)+(5-E5)+(F5-1)+(5-G5)+(H5-1)+(5-I5)+(J5-1)+(5-K5)),"") -> 52.5 | M5: =IF(A5="","",IF(COUNT(B5:K5)=10,"Yes","No")) | N5: SYNTHETIC PROXY EVALUATION ONLY — not a human participant session; validate with real Android users.
B6: 4 | C6: 2 | D6: 4 | E6: 2 | F6: 4 | G6: 2 | H6: 4 | I6: 2 | J6: 4 | K6: 2 | L6: =IF(COUNT(B6:K6)=10,2.5*((B6-1)+(5-C6)+(D6-1)+(5-E6)+(F6-1)+(5-G6)+(H6-1)+(5-I6)+(J6-1)+(5-K6)),"") -> 75 | M6: =IF(A6="","",IF(COUNT(B6:K6)=10,"Yes","No")) | N6: SYNTHETIC PROXY EVALUATION ONLY — not a human participant session; validate with real Android users.
L7: =IF(COUNT(B7:K7)=10,2.5*((B7-1)+(5-C7)+(D7-1)+(5-E7)+(F7-1)+(5-G7)+(H7-1)+(5-I7)+(J7-1)+(5-K7)),"") | M7: =IF(A7="","",IF(COUNT(B7:K7)=10,"Yes","No"))
L8: =IF(COUNT(B8:K8)=10,2.5*((B8-1)+(5-C8)+(D8-1)+(5-E8)+(F8-1)+(5-G8)+(H8-1)+(5-I8)+(J8-1)+(5-K8)),"") | M8: =IF(A8="","",IF(COUNT(B8:K8)=10,"Yes","No"))
L9: =IF(COUNT(B9:K9)=10,2.5*((B9-1)+(5-C9)+(D9-1)+(5-E9)+(F9-1)+(5-G9)+(H9-1)+(5-I9)+(J9-1)+(5-K9)),"") | M9: =IF(A9="","",IF(COUNT(B9:K9)=10,"Yes","No"))
L10: =IF(COUNT(B10:K10)=10,2.5*((B10-1)+(5-C10)+(D10-1)+(5-E10)+(F10-1)+(5-G10)+(H10-1)+(5-I10)+(J10-1)+(5-K10)),"") | M10: =IF(A10="","",IF(COUNT(B10:K10)=10,"Yes","No"))
L11: =IF(COUNT(B11:K11)=10,2.5*((B11-1)+(5-C11)+(D11-1)+(5-E11)+(F11-1)+(5-G11)+(H11-1)+(5-I11)+(J11-1)+(5-K11)),"") | M11: =IF(A11="","",IF(COUNT(B11:K11)=10,"Yes","No"))
L12: =IF(COUNT(B12:K12)=10,2.5*((B12-1)+(5-C12)+(D12-1)+(5-E12)+(F12-1)+(5-G12)+(H12-1)+(5-I12)+(J12-1)+(5-K12)),"") | M12: =IF(A12="","",IF(COUNT(B12:K12)=10,"Yes","No"))
L13: =IF(COUNT(B13:K13)=10,2.5*((B13-1)+(5-C13)+(D13-1)+(5-E13)+(F13-1)+(5-G13)+(H13-1)+(5-I13)+(J13-1)+(5-K13)),"") | M13: =IF(A13="","",IF(COUNT(B13:K13)=10,"Yes","No"))
L14: =IF(COUNT(B14:K14)=10,2.5*((B14-1)+(5-C14)+(D14-1)+(5-E14)+(F14-1)+(5-G14)+(H14-1)+(5-I14)+(J14-1)+(5-K14)),"") | M14: =IF(A14="","",IF(COUNT(B14:K14)=10,"Yes","No"))
L15: =IF(COUNT(B15:K15)=10,2.5*((B15-1)+(5-C15)+(D15-1)+(5-E15)+(F15-1)+(5-G15)+(H15-1)+(5-I15)+(J15-1)+(5-K15)),"") | M15: =IF(A15="","",IF(COUNT(B15:K15)=10,"Yes","No"))
L16: =IF(COUNT(B16:K16)=10,2.5*((B16-1)+(5-C16)+(D16-1)+(5-E16)+(F16-1)+(5-G16)+(H16-1)+(5-I16)+(J16-1)+(5-K16)),"") | M16: =IF(A16="","",IF(COUNT(B16:K16)=10,"Yes","No"))
A19: Scoring (Brooke, 1996): odd items score-1, even items 5-score, sum the ten values, multiply by 2.5 (0-100). It is NOT a percentage and NOT the mean of the raw answers.
A21: Q1 | B21: I think that I would like to use this system frequently.
A22: Q2 | B22: I found the system unnecessarily complex.
A23: Q3 | B23: I thought the system was easy to use.
A24: Q4 | B24: I think that I would need the support of a technical person to be able to use this system.
A25: Q5 | B25: I found the various functions in this system were well integrated.
A26: Q6 | B26: I thought there was too much inconsistency in this system.
A27: Q7 | B27: I would imagine that most people would learn to use this system very quickly.
A28: Q8 | B28: I found the system very cumbersome to use.
A29: Q9 | B29: I felt very confident using the system.
A30: Q10 | B30: I needed to learn a lot of things before I could get going with this system.

Sheet Issues
A1: Issue ID | B1: Related task | C1: Source | D1: Issue description | E1: Evidence (screenshot / video ref / file:line) | F1: Participants affected (n) | G1: Frequency (auto = n / N) | H1: Severity 0-4 (Nielsen) | I1: Severity label (auto) | J1: Impact on task completion | K1: Reproducibility | L1: Recommended improvement | M1: Status | N1: Related prototype issue | O1: Date logged | P1: Notes
G2: =IF(OR(F2="",N('Severity Scale'!$B$2)=0),"",F2/'Severity Scale'!$B$2) | I2: =IF(H2="","",IFERROR(INDEX('Severity Scale'!$B$5:$B$9,H2+1)&" ("&INDEX('Severity Scale'!$C$5:$C$9,H2+1)&")",""))
G3: =IF(OR(F3="",N('Severity Scale'!$B$2)=0),"",F3/'Severity Scale'!$B$2) | I3: =IF(H3="","",IFERROR(INDEX('Severity Scale'!$B$5:$B$9,H3+1)&" ("&INDEX('Severity Scale'!$C$5:$C$9,H3+1)&")",""))
G4: =IF(OR(F4="",N('Severity Scale'!$B$2)=0),"",F4/'Severity Scale'!$B$2) | I4: =IF(H4="","",IFERROR(INDEX('Severity Scale'!$B$5:$B$9,H4+1)&" ("&INDEX('Severity Scale'!$C$5:$C$9,H4+1)&")",""))
G5: =IF(OR(F5="",N('Severity Scale'!$B$2)=0),"",F5/'Severity Scale'!$B$2) | I5: =IF(H5="","",IFERROR(INDEX('Severity Scale'!$B$5:$B$9,H5+1)&" ("&INDEX('Severity Scale'!$C$5:$C$9,H5+1)&")",""))
G6: =IF(OR(F6="",N('Severity Scale'!$B$2)=0),"",F6/'Severity Scale'!$B$2) | I6: =IF(H6="","",IFERROR(INDEX('Severity Scale'!$B$5:$B$9,H6+1)&" ("&INDEX('Severity Scale'!$C$5:$C$9,H6+1)&")",""))
G7: =IF(OR(F7="",N('Severity Scale'!$B$2)=0),"",F7/'Severity Scale'!$B$2) | I7: =IF(H7="","",IFERROR(INDEX('Severity Scale'!$B$5:$B$9,H7+1)&" ("&INDEX('Severity Scale'!$C$5:$C$9,H7+1)&")",""))
A8: WA-P01 | B8: T3 | C8: Proxy evaluation (synthetic; not participant) | D8: “Responded” does not map directly to the accepted, contacted, waiting and declined counters, causing inconsistent interpretations. | E8: Proxy task traces P01, P02, P03 | F8: 3 | G8: =IF(OR(F8="",N('Severity Scale'!$B$2)=0),"",F8/'Severity Scale'!$B$2) -> 0.6 | H8: 3 | I8: =IF(H8="","",IFERROR(INDEX('Severity Scale'!$B$5:$B$9,H8+1)&" ("&INDEX('Severity Scale'!$C$5:$C$9,H8+1)&")","")) -> Major problem (High) | J8: Required assistance or produced an ambiguous answer. | K8: Always in this proxy evaluation | L8: Label the task and request summary consistently, or add a clearly named response total. | M8: Proxy finding — validate with people | N8: UI-03
A9: WA-P02 | B9: T4 | C9: Proxy evaluation (synthetic; not participant) | D9: Setting an exact “until 6 pm” availability time is less discoverable than the relative availability options. | E9: Proxy task traces P01–P05 | F9: 5 | G9: =IF(OR(F9="",N('Severity Scale'!$B$2)=0),"",F9/'Severity Scale'!$B$2) -> 1 | H9: 3 | I9: =IF(H9="","",IFERROR(INDEX('Severity Scale'!$B$5:$B$9,H9+1)&" ("&INDEX('Severity Scale'!$C$5:$C$9,H9+1)&")","")) -> Major problem (High) | J9: One abandonment and four assisted completions. | K9: Always in this proxy evaluation | L9: Add an “Until 6 pm today” shortcut and simplify the exact-time flow. | M9: Proxy finding — validate with people | N9: UI-01
A10: WA-P03 | B10: T2 | C10: Proxy evaluation (synthetic; not participant) | D10: The relationship detail expected by the scenario is optional and hidden in an expandable section. | E10: Proxy task traces P01, P04 | F10: 2 | G10: =IF(OR(F10="",N('Severity Scale'!$B$2)=0),"",F10/'Severity Scale'!$B$2) -> 0.4 | H10: 2 | I10: =IF(H10="","",IFERROR(INDEX('Severity Scale'!$B$5:$B$9,H10+1)&" ("&INDEX('Severity Scale'!$C$5:$C$9,H10+1)&")","")) -> Minor problem (Medium) | J10: Caused hesitation and one assisted completion. | K10: Sometimes in this proxy evaluation | L10: Keep optional details grouped but make their availability clearer in the request flow. | M10: Proxy finding — validate with people | N10: None
A11: WA-P04 | B11: T6 | C11: Proxy evaluation (synthetic; not participant) | D11: History is not available as a tab, leading first-time users to search the tab bar before finding a secondary path. | E11: Proxy task traces P01, P03, P04 | F11: 3 | G11: =IF(OR(F11="",N('Severity Scale'!$B$2)=0),"",F11/'Severity Scale'!$B$2) -> 0.6 | H11: 3 | I11: =IF(H11="","",IFERROR(INDEX('Severity Scale'!$B$5:$B$9,H11+1)&" ("&INDEX('Severity Scale'!$C$5:$C$9,H11+1)&")","")) -> Major problem (High) | J11: Three assisted completions. | K11: Always in this proxy evaluation | L11: Expose History more prominently or add it to a primary navigation surface. | M11: Proxy finding — validate with people | N11: UI-04
G12: =IF(OR(F12="",N('Severity Scale'!$B$2)=0),"",F12/'Severity Scale'!$B$2) | I12: =IF(H12="","",IFERROR(INDEX('Severity Scale'!$B$5:$B$9,H12+1)&" ("&INDEX('Severity Scale'!$C$5:$C$9,H12+1)&")",""))
G13: =IF(OR(F13="",N('Severity Scale'!$B$2)=0),"",F13/'Severity Scale'!$B$2) | I13: =IF(H13="","",IFERROR(INDEX('Severity Scale'!$B$5:$B$9,H13+1)&" ("&INDEX('Severity Scale'!$C$5:$C$9,H13+1)&")",""))
G14: =IF(OR(F14="",N('Severity Scale'!$B$2)=0),"",F14/'Severity Scale'!$B$2) | I14: =IF(H14="","",IFERROR(INDEX('Severity Scale'!$B$5:$B$9,H14+1)&" ("&INDEX('Severity Scale'!$C$5:$C$9,H14+1)&")",""))
G15: =IF(OR(F15="",N('Severity Scale'!$B$2)=0),"",F15/'Severity Scale'!$B$2) | I15: =IF(H15="","",IFERROR(INDEX('Severity Scale'!$B$5:$B$9,H15+1)&" ("&INDEX('Severity Scale'!$C$5:$C$9,H15+1)&")",""))
G16: =IF(OR(F16="",N('Severity Scale'!$B$2)=0),"",F16/'Severity Scale'!$B$2) | I16: =IF(H16="","",IFERROR(INDEX('Severity Scale'!$B$5:$B$9,H16+1)&" ("&INDEX('Severity Scale'!$C$5:$C$9,H16+1)&")",""))
G17: =IF(OR(F17="",N('Severity Scale'!$B$2)=0),"",F17/'Severity Scale'!$B$2) | I17: =IF(H17="","",IFERROR(INDEX('Severity Scale'!$B$5:$B$9,H17+1)&" ("&INDEX('Severity Scale'!$C$5:$C$9,H17+1)&")",""))
G18: =IF(OR(F18="",N('Severity Scale'!$B$2)=0),"",F18/'Severity Scale'!$B$2) | I18: =IF(H18="","",IFERROR(INDEX('Severity Scale'!$B$5:$B$9,H18+1)&" ("&INDEX('Severity Scale'!$C$5:$C$9,H18+1)&")",""))
G19: =IF(OR(F19="",N('Severity Scale'!$B$2)=0),"",F19/'Severity Scale'!$B$2) | I19: =IF(H19="","",IFERROR(INDEX('Severity Scale'!$B$5:$B$9,H19+1)&" ("&INDEX('Severity Scale'!$C$5:$C$9,H19+1)&")",""))
G20: =IF(OR(F20="",N('Severity Scale'!$B$2)=0),"",F20/'Severity Scale'!$B$2) | I20: =IF(H20="","",IFERROR(INDEX('Severity Scale'!$B$5:$B$9,H20+1)&" ("&INDEX('Severity Scale'!$C$5:$C$9,H20+1)&")",""))
G21: =IF(OR(F21="",N('Severity Scale'!$B$2)=0),"",F21/'Severity Scale'!$B$2) | I21: =IF(H21="","",IFERROR(INDEX('Severity Scale'!$B$5:$B$9,H21+1)&" ("&INDEX('Severity Scale'!$C$5:$C$9,H21+1)&")",""))
G22: =IF(OR(F22="",N('Severity Scale'!$B$2)=0),"",F22/'Severity Scale'!$B$2) | I22: =IF(H22="","",IFERROR(INDEX('Severity Scale'!$B$5:$B$9,H22+1)&" ("&INDEX('Severity Scale'!$C$5:$C$9,H22+1)&")",""))
G23: =IF(OR(F23="",N('Severity Scale'!$B$2)=0),"",F23/'Severity Scale'!$B$2) | I23: =IF(H23="","",IFERROR(INDEX('Severity Scale'!$B$5:$B$9,H23+1)&" ("&INDEX('Severity Scale'!$C$5:$C$9,H23+1)&")",""))
... G100: =IF(OR(F100="",N('Severity Scale'!$B$2)=0),"",F100/'Severity Scale'!$B$2) | I100: =IF(H100="","",IFERROR(INDEX('Severity Scale'!$B$5:$B$9,H100+1)&" ("&INDEX('Severity Scale'!$C$5:$C$9,H100+1)&")",""))

Sheet Severity Scale
A1: Severity scale and participant count
A2: Participants tested (N) | B2: =Summary!B4 -> 5 | C2: Denominator for 'Frequency'. Linked to the participant count in Summary.
A4: Level | B4: Nielsen label (PDF §9.3: Nielsen 0-4) | C4: Low / Medium / High | D4: How it is assigned
A5: 0 | B5: Not a usability problem | C5: None | D5: Disagreement among evaluators; no effect on any participant.
A6: 1 | B6: Cosmetic problem | C6: Low | D6: Noticed by participants but caused no error, delay or comment about difficulty.
A7: 2 | B7: Minor problem | C7: Medium | D7: Caused hesitation, a wrong tap or a recovery without help; low priority to fix.
A8: 3 | B8: Major problem | C8: High | D8: Needed assistance, or many participants made errors; important to fix before release.
A9: 4 | B9: Usability catastrophe | C9: High | D9: Prevented task completion for one or more participants; must be fixed.
A11: Rate by combining three factors (Nielsen): how often it happens, how big the impact is when it happens, and whether people can get past it once they know.
A12: Frequency alone never sets severity: one participant who could not finish a task is still level 4 for that participant; say so in the description.
A13: Candidate rows (ID CAND-nn) come from reading the code, not from watching people. They stay 'Needs verification' with no severity until observed.
A14: With n = 5 to 8, report counts (e.g. 3/6) rather than percentages, and state the small-sample caveat (PDF §9.3).

Sheet Tasks
A1: Task ID | B1: Title | C1: Scenario given to participant (PDF Table 15, abridged) | D1: Success criterion (PDF Table 15) | E1: Reqs / issue
A2: T1 | B2: Sign in | C2: You are new to DonorLink. Sign in with the test account you were given. | D2: Reaches Home without help | E2: NFR08
A3: T2 | B3: Create emergency request | C3: Your uncle needs 2 units of O+ blood urgently at a hospital in Colombo. Ask for help using the app. | D3: Request submitted and listed as waiting for verification | E3: FR01, NFR01
A4: T3 | B4: Check status and response count | C4: Find out whether your request has been verified and how many donors have responded. | D4: States the correct status and response count | E4: FR03, FR07, UI-03
A5: T4 | B5: Set donor availability | C5: You can donate today until 6 pm. Make sure the app knows this. | D5: Availability set to available with an end time | E5: FR04, UI-01
A6: T5 | B6: Respond to an alert | C6: You received an alert asking for your blood group. Look at it and agree to donate. | D6: Opens the alert and accepts the right request | E6: FR05, FR06, UI-05
A7: T6 | B7: Find history | C7: Find your donation and request history. | D7: History opened and a past record identified | E7: FR10, UI-04
A9: Source: IT3060 Milestones 01-03 Final Report, Table 15. Full facilitator wording and observable criteria: task-scenarios.md and task-success-criteria.md.

Sheet Lists
A1: Outcomes | B1: Task IDs | C1: Environment | D1: Impact | E1: Reproducibility | F1: Status | G1: Prototype issue | H1: Source
